Workbook

Sheet Σύνοψη
A1: Anbit – Σύνοψη καμπάνιας Instagram
A2: Λογαριασμοί που συγκεντρώθηκαν στις 08/10/2026. Οι αριθμοί ενημερώνονται μόνοι τους.
A4: Πόλη | B4: A | C4: B | D4: C | E4: Σύνολο
A5: Αθήνα | B5: =COUNTIFS(Λογαριασμοί!$F$5:$F$203,$A5,Λογαριασμοί!$I$5:$I$203,"A") -> 63 | C5: =COUNTIFS(Λογαριασμοί!$F$5:$F$203,$A5,Λογαριασμοί!$I$5:$I$203,"B") -> 34 | D5: =COUNTIFS(Λογαριασμοί!$F$5:$F$203,$A5,Λογαριασμοί!$I$5:$I$203,"C") -> 9 | E5: =SUM(B5:D5) -> 106
A6: Θεσσαλονίκη | B6: =COUNTIFS(Λογαριασμοί!$F$5:$F$203,$A6,Λογαριασμοί!$I$5:$I$203,"A") -> 42 | C6: =COUNTIFS(Λογαριασμοί!$F$5:$F$203,$A6,Λογαριασμοί!$I$5:$I$203,"B") -> 48 | D6: =COUNTIFS(Λογαριασμοί!$F$5:$F$203,$A6,Λογαριασμοί!$I$5:$I$203,"C") -> 3 | E6: =SUM(B6:D6) -> 93
A7: Σύνολο | B7: =SUM(B5:B6) -> 105 | C7: =SUM(C5:C6) -> 82 | D7: =SUM(D5:D6) -> 12 | E7: =SUM(E5:E6) -> 199
A9: Κατάσταση | B9: Αθήνα | C9: Θεσσαλονίκη | D9: Σύνολο
A10: Δεν στάλθηκε | B10: =COUNTIFS(Λογαριασμοί!$L$5:$L$203,$A10,Λογαριασμοί!$F$5:$F$203,"Αθήνα") -> 106 | C10: =COUNTIFS(Λογαριασμοί!$L$5:$L$203,$A10,Λογαριασμοί!$F$5:$F$203,"Θεσσαλονίκη") -> 93 | D10: =B10+C10 -> 199
A11: Στάλθηκε | B11: =COUNTIFS(Λογαριασμοί!$L$5:$L$203,$A11,Λογαριασμοί!$F$5:$F$203,"Αθήνα") -> 0 | C11: =COUNTIFS(Λογαριασμοί!$L$5:$L$203,$A11,Λογαριασμοί!$F$5:$F$203,"Θεσσαλονίκη") -> 0 | D11: =B11+C11 -> 0
A12: Follow-up στάλθηκε | B12: =COUNTIFS(Λογαριασμοί!$L$5:$L$203,$A12,Λογαριασμοί!$F$5:$F$203,"Αθήνα") -> 0 | C12: =COUNTIFS(Λογαριασμοί!$L$5:$L$203,$A12,Λογαριασμοί!$F$5:$F$203,"Θεσσαλονίκη") -> 0 | D12: =B12+C12 -> 0
A13: Ενδιαφέρεται | B13: =COUNTIFS(Λογαριασμοί!$L$5:$L$203,$A13,Λογαριασμοί!$F$5:$F$203,"Αθήνα") -> 0 | C13: =COUNTIFS(Λογαριασμοί!$L$5:$L$203,$A13,Λογαριασμοί!$F$5:$F$203,"Θεσσαλονίκη") -> 0 | D13: =B13+C13 -> 0
A14: Ραντεβού / Demo | B14: =COUNTIFS(Λογαριασμοί!$L$5:$L$203,$A14,Λογαριασμοί!$F$5:$F$203,"Αθήνα") -> 0 | C14: =COUNTIFS(Λογαριασμοί!$L$5:$L$203,$A14,Λογαριασμοί!$F$5:$F$203,"Θεσσαλονίκη") -> 0 | D14: =B14+C14 -> 0
A15: Συνεργάτης | B15: =COUNTIFS(Λογαριασμοί!$L$5:$L$203,$A15,Λογαριασμοί!$F$5:$F$203,"Αθήνα") -> 0 | C15: =COUNTIFS(Λογαριασμοί!$L$5:$L$203,$A15,Λογαριασμοί!$F$5:$F$203,"Θεσσαλονίκη") -> 0 | D15: =B15+C15 -> 0
A16: Δεν ενδιαφέρεται | B16: =COUNTIFS(Λογαριασμοί!$L$5:$L$203,$A16,Λογαριασμοί!$F$5:$F$203,"Αθήνα") -> 0 | C16: =COUNTIFS(Λογαριασμοί!$L$5:$L$203,$A16,Λογαριασμοί!$F$5:$F$203,"Θεσσαλονίκη") -> 0 | D16: =B16+C16 -> 0
A17: Δεν απάντησε | B17: =COUNTIFS(Λογαριασμοί!$L$5:$L$203,$A17,Λογαριασμοί!$F$5:$F$203,"Αθήνα") -> 0 | C17: =COUNTIFS(Λογαριασμοί!$L$5:$L$203,$A17,Λογαριασμοί!$F$5:$F$203,"Θεσσαλονίκη") -> 0 | D17: =B17+C17 -> 0
A19: Ποσοστό απάντησης | B19: =IF((COUNTA(Λογαριασμοί!$L$5:$L$203)-COUNTIF(Λογαριασμοί!$L$5:$L$203,"Δεν στάλθηκε"))=0,0,(COUNTIF(Λογαριασμοί!$L$5:$L$203,"Ενδιαφέρεται")+COUNTIF(Λογαριασμοί!$L$5:$L$203,"Ραντεβού / Demo")+COUNTIF(Λογαριασμοί!$L$5:$L$203,"Συνεργάτης")+COUNTIF(Λογαριασμοί!$L$5:$L$203,"Δεν ενδιαφέρεται"))/(COUNTA(Λογαριασμοί!$L$5:$L$203)-COUNTIF(Λογαριασμοί!$L$5:$L$203,"Δεν στάλθηκε"))) -> 0 | C19: απαντήσεις ÷ μηνύματα που στάλθηκαν
A21: Πώς βγήκε η λίστα & πώς τη χρησιμοποιείς
A22: • Δημόσια επαγγελματικά προφίλ Instagram (καφέ, all-day, brunch, bars, μεζεδοπωλεία, ταβέρνες, street food) σε Αθήνα και Θεσσαλονίκη, μαζί με όσα στοιχεία γράφουν τα ίδια στο bio τους (διεύθυνση, ωράριο, τηλέφωνο).
A23: • Προτεραιότητα A: καφέ / all-day / brunch με τραπέζια και πελάτες που έρχονται συχνά, άρα το καλύτερο ταίριασμα για QR + πόντους. B: bars, ταβέρνες, μεζεδοπωλεία, εστιατόρια, street food. C: κυρίως take away, ζαχαροπλαστεία ή αλυσίδες/franchise.
A24: • Η στήλη «Προς επιβεβαίωση» σημειώνει όσα δεν έγραφαν καθαρά περιοχή ή είδος μαγαζιού. Ρίξε μια ματιά στο προφίλ πριν στείλεις.
A25: • Στείλε από τον επαγγελματικό λογαριασμό της Anbit. Τα μηνύματα σε λογαριασμούς που δεν σε ακολουθούν πάνε στα «Αιτήματα μηνυμάτων», οπότε ένα follow και ένα like πριν το μήνυμα βοηθάνε να το δουν.
A26: • Μην στέλνεις μαζικά: περίπου 20-30 νέα μηνύματα την ημέρα, με λίγο διαφορετικό κείμενο, για να μη σε περιορίσει το Instagram.
A27: • Γράψε την ημερομηνία στο «Ημ/νία 1ου μηνύματος» και το «Follow-up στις» βγαίνει μόνο του 4 μέρες μετά.

Sheet Λογαριασμοί
A1: Anbit – Λογαριασμοί Instagram για συνεργασία (Αθήνα & Θεσσαλονίκη)
A2: Συμπληρώνεις μόνο τις κίτρινες στήλες: Κατάσταση, Ημ/νία 1ου μηνύματος, Σημειώσεις. Το «Στείλε DM» ανοίγει κατευθείαν συνομιλία στο Instagram. Το «Έτοιμο μήνυμα» βγαίνει από το φύλλο Μηνύματα.
A4: # | B4: Κατάστημα | C4: Instagram | D4: Προφίλ | E4: Στείλε DM | F4: Πόλη | G4: Περιοχή / Διεύθυνση | H4: Κατηγορία | I4: Προτεραιότητα | J4: Στοιχεία από το bio | K4: Προς επιβεβαίωση | L4: Κατάσταση | M4: Ημ/νία 1ου μηνύματος | N4: Follow-up στις | O4: Σημειώσεις | P4: Έτοιμο μήνυμα
A5: 1 | B5: Adonis Premises / Alemania's | C5: @adonis_alemanias | D5: Άνοιγμα | E5: Μήνυμα | F5: Αθήνα | G5: Νέα Σμύρνη (25ης Μαρτίου 11) | H5: Κρέας & Μπύρα / Cafe | I5: A | L5: Δεν στάλθηκε | N5: =IF(M5="","",M5+4) | P5: =SUBSTITUTE(SUBSTITUTE(IF(I5="A",Μηνύματα!$B$7,Μηνύματα!$B$8),"{ΚΑΤΑΣΤΗΜΑ}",B5),"{ΟΝΟΜΑ}",Μηνύματα!$B$4) -> Γεια σας! 👋 Είμαι ο/η [Το όνομά σου] από την Anbit (anbit.gr). Μας άρεσε πολύ το Adonis Premises / Alemania's και θα θέλαμε να σας προτείνουμε μια συνεργασία. Η Anbit είναι παραγγελία από το τραπέζι με QR + σύστημα επιβράβευσης πελατών: • Ο πελάτης σκανάρει το QR, βλέπει το μενού με φωτογραφίες (Ελληνικά/Αγγλικά) και παραγγέλνει, χωρίς εφαρμογή • Η παραγγελία έρχεται στο κινητό ή στο tablet σας με τον αριθμό τραπεζιού • Με κάθε παραγγελία μαζεύει πόντους (XP) που εξαργυρώνονται μόνο στο δικό σας μαγαζί, οπότε έχει λόγο να ξαναέρθει • Βλέπετε ποιος έρχεται, πόσο συχνά και τι παίρνει • Δεν αλλάζει τίποτα στο ταμείο: ίδιο POS, 0% προμήθεια, το στήνουμε εμείς σε 10 λεπτά • Δωρεάν προβολή στα TikTok/Instagram της Anbit και στον χάρτη της Anbit Θα σας ενδιέφερε να σας το δείξουμε από κοντά σε 10 λεπτά, όποτε σας βολεύει;
A6: 2 | B6: Aroma Cafe Bar | C6: @aroma.cafe.bar.gizi | D6: Άνοιγμα | E6: Μήνυμα | F6: Αθήνα | G6: Γκύζη | H6: Cafe-Bar / Brunch | I6: A | J6: Από το 1996 | L6: Δεν στάλθηκε | N6: =IF(M6="","",M6+4) | P6: =SUBSTITUTE(SUBSTITUTE(IF(I6="A",Μηνύματα!$B$7,Μηνύματα!$B$8),"{ΚΑΤΑΣΤΗΜΑ}",B6),"{ΟΝΟΜΑ}",Μηνύματα!$B$4) -> Γεια σας! 👋 Είμαι ο/η [Το όνομά σου] από την Anbit (anbit.gr). Μας άρεσε πολύ το Aroma Cafe Bar και θα θέλαμε να σας προτείνουμε μια συνεργασία. Η Anbit είναι παραγγελία από το τραπέζι με QR + σύστημα επιβράβευσης πελατών: • Ο πελάτης σκανάρει το QR, βλέπει το μενού με φωτογραφίες (Ελληνικά/Αγγλικά) και παραγγέλνει, χωρίς εφαρμογή • Η παραγγελία έρχεται στο κινητό ή στο tablet σας με τον αριθμό τραπεζιού • Με κάθε παραγγελία μαζεύει πόντους (XP) που εξαργυρώνονται μόνο στο δικό σας μαγαζί, οπότε έχει λόγο να ξαναέρθει • Βλέπετε ποιος έρχεται, πόσο συχνά και τι παίρνει • Δεν αλλάζει τίποτα στο ταμείο: ίδιο POS, 0% προμήθεια, το στήνουμε εμείς σε 10 λεπτά • Δωρεάν προβολή στα TikTok/Instagram της Anbit και στον χάρτη της Anbit Θα σας ενδιέφερε να σας το δείξουμε από κοντά σε 10 λεπτά, όποτε σας βολεύει;
A7: 3 | B7: Athénée | C7: @atheneeathens | D7: Άνοιγμα | E7: Μήνυμα | F7: Αθήνα | G7: Κέντρο | H7: Cafe-Restaurant | I7: A | J7: Ιστορικό, στον οδηγό Michelin | L7: Δεν στάλθηκε | N7: =IF(M7="","",M7+4) | P7: =SUBSTITUTE(SUBSTITUTE(IF(I7="A",Μηνύματα!$B$7,Μηνύματα!$B$8),"{ΚΑΤΑΣΤΗΜΑ}",B7),"{ΟΝΟΜΑ}",Μηνύματα!$B$4) -> Γεια σας! 👋 Είμαι ο/η [Το όνομά σου] από την Anbit (anbit.gr). Μας άρεσε πολύ το Athénée και θα θέλαμε να σας προτείνουμε μια συνεργασία. Η Anbit είναι παραγγελία από το τραπέζι με QR + σύστημα επιβράβευσης πελατών: • Ο πελάτης σκανάρει το QR, βλέπει το μενού με φωτογραφίες (Ελληνικά/Αγγλικά) και παραγγέλνει, χωρίς εφαρμογή • Η παραγγελία έρχεται στο κινητό ή στο tablet σας με τον αριθμό τραπεζιού • Με κάθε παραγγελία μαζεύει πόντους (XP) που εξαργυρώνονται μόνο στο δικό σας μαγαζί, οπότε έχει λόγο να ξαναέρθει • Βλέπετε ποιος έρχεται, πόσο συχνά και τι παίρνει • Δεν αλλάζει τίποτα στο ταμείο: ίδιο POS, 0% προμήθεια, το στήνουμε εμείς σε 10 λεπτά • Δωρεάν προβολή στα TikTok/Instagram της Anbit και στον χάρτη της Anbit Θα σας ενδιέφερε να σας το δείξουμε από κοντά σε 10 λεπτά, όποτε σας βολεύει;
A8: 4 | B8: BAR IDEAL | C8: @im.notinathens | D8: Άνοιγμα | E8: Μήνυμα | F8: Αθήνα | G8: Κέντρο | H8: Coffee & Spirits / Hi-Fi bar | I8: A | J8: 09:00-03:00 | L8: Δεν στάλθηκε | N8: =IF(M8="","",M8+4) | P8: =SUBSTITUTE(SUBSTITUTE(IF(I8="A",Μηνύματα!$B$7,Μηνύματα!$B$8),"{ΚΑΤΑΣΤΗΜΑ}",B8),"{ΟΝΟΜΑ}",Μηνύματα!$B$4) -> Γεια σας! 👋 Είμαι ο/η [Το όνομά σου] από την Anbit (anbit.gr). Μας άρεσε πολύ το BAR IDEAL και θα θέλαμε να σας προτείνουμε μια συνεργασία. Η Anbit είναι παραγγελία από το τραπέζι με QR + σύστημα επιβράβευσης πελατών: • Ο πελάτης σκανάρει το QR, βλέπει το μενού με φωτογραφίες (Ελληνικά/Αγγλικά) και παραγγέλνει, χωρίς εφαρμογή • Η παραγγελία έρχεται στο κινητό ή στο tablet σας με τον αριθμό τραπεζιού • Με κάθε παραγγελία μαζεύει πόντους (XP) που εξαργυρώνονται μόνο στο δικό σας μαγαζί, οπότε έχει λόγο να ξαναέρθει • Βλέπετε ποιος έρχεται, πόσο συχνά και τι παίρνει • Δεν αλλάζει τίποτα στο ταμείο: ίδιο POS, 0% προμήθεια, το στήνουμε εμείς σε 10 λεπτά • Δωρεάν προβολή στα TikTok/Instagram της Anbit και στον χάρτη της Anbit Θα σας ενδιέφερε να σας το δείξουμε από κοντά σε 10 λεπτά, όποτε σας βολεύει;
A9: 5 | B9: Barista's Nea Smyrni | C9: @baristas_neasmirni | D9: Άνοιγμα | E9: Μήνυμα | F9: Αθήνα | G9: Νέα Σμύρνη (Λ. Ελ. Βενιζέλου 140) | H9: Coffee | I9: A | L9: Δεν στάλθηκε | N9: =IF(M9="","",M9+4) | P9: =SUBSTITUTE(SUBSTITUTE(IF(I9="A",Μηνύματα!$B$7,Μηνύματα!$B$8),"{ΚΑΤΑΣΤΗΜΑ}",B9),"{ΟΝΟΜΑ}",Μηνύματα!$B$4) -> Γεια σας! 👋 Είμαι ο/η [Το όνομά σου] από την Anbit (anbit.gr). Μας άρεσε πολύ το Barista's Nea Smyrni και θα θέλαμε να σας προτείνουμε μια συνεργασία. Η Anbit είναι παραγγελία από το τραπέζι με QR + σύστημα επιβράβευσης πελατών: • Ο πελάτης σκανάρει το QR, βλέπει το μενού με φωτογραφίες (Ελληνικά/Αγγλικά) και παραγγέλνει, χωρίς εφαρμογή • Η παραγγελία έρχεται στο κινητό ή στο tablet σας με τον αριθμό τραπεζιού • Με κάθε παραγγελία μαζεύει πόντους (XP) που εξαργυρώνονται μόνο στο δικό σας μαγαζί, οπότε έχει λόγο να ξαναέρθει • Βλέπετε ποιος έρχεται, πόσο συχνά και τι παίρνει • Δεν αλλάζει τίποτα στο ταμείο: ίδιο POS, 0% προμήθεια, το στήνουμε εμείς σε 10 λεπτά • Δωρεάν προβολή στα TikTok/Instagram της Anbit και στον χάρτη της Anbit Θα σας ενδιέφερε να σας το δείξουμε από κοντά σε 10 λεπτά, όποτε σας βολεύει;
A10: 6 | B10: Bistro Cafe | C10: @bistro_cafe_bar_restaurant | D10: Άνοιγμα | E10: Μήνυμα | F10: Αθήνα | G10: Γαλάτσι | H10: All-day Cafe-Restaurant-Cocktail bar | I10: A | L10: Δεν στάλθηκε | N10: =IF(M10="","",M10+4) | P10: =SUBSTITUTE(SUBSTITUTE(IF(I10="A",Μηνύματα!$B$7,Μηνύματα!$B$8),"{ΚΑΤΑΣΤΗΜΑ}",B10),"{ΟΝΟΜΑ}",Μηνύματα!$B$4) -> Γεια σας! 👋 Είμαι ο/η [Το όνομά σου] από την Anbit (anbit.gr). Μας άρεσε πολύ το Bistro Cafe και θα θέλαμε να σας προτείνουμε μια συνεργασία. Η Anbit είναι παραγγελία από το τραπέζι με QR + σύστημα επιβράβευσης πελατών: • Ο πελάτης σκανάρει το QR, βλέπει το μενού με φωτογραφίες (Ελληνικά/Αγγλικά) και παραγγέλνει, χωρίς εφαρμογή • Η παραγγελία έρχεται στο κινητό ή στο tablet σας με τον αριθμό τραπεζιού • Με κάθε παραγγελία μαζεύει πόντους (XP) που εξαργυρώνονται μόνο στο δικό σας μαγαζί, οπότε έχει λόγο να ξαναέρθει • Βλέπετε ποιος έρχεται, πόσο συχνά και τι παίρνει • Δεν αλλάζει τίποτα στο ταμείο: ίδιο POS, 0% προμήθεια, το στήνουμε εμείς σε 10 λεπτά • Δωρεάν προβολή στα TikTok/Instagram της Anbit και στον χάρτη της Anbit Θα σας ενδιέφερε να σας το δείξουμε από κοντά σε 10 λεπτά, όποτε σας βολεύει;
A11: 7 | B11: Black Duck Museum Bistro | C11: @black_duck_athens | D11: Άνοιγμα | E11: Μήνυμα | F11: Αθήνα | G11: Κέντρο | H11: All-day Bistro / Brunch | I11: A | J11: Κρατήσεις τραπεζιών | L11: Δεν στάλθηκε | N11: =IF(M11="","",M11+4) | P11: =SUBSTITUTE(SUBSTITUTE(IF(I11="A",Μηνύματα!$B$7,Μηνύματα!$B$8),"{ΚΑΤΑΣΤΗΜΑ}",B11),"{ΟΝΟΜΑ}",Μηνύματα!$B$4) -> Γεια σας! 👋 Είμαι ο/η [Το όνομά σου] από την Anbit (anbit.gr). Μας άρεσε πολύ το Black Duck Museum Bistro και θα θέλαμε να σας προτείνουμε μια συνεργασία. Η Anbit είναι παραγγελία από το τραπέζι με QR + σύστημα επιβράβευσης πελατών: • Ο πελάτης σκανάρει το QR, βλέπει το μενού με φωτογραφίες (Ελληνικά/Αγγλικά) και παραγγέλνει, χωρίς εφαρμογή • Η παραγγελία έρχεται στο κινητό ή στο tablet σας με τον αριθμό τραπεζιού • Με κάθε παραγγελία μαζεύει πόντους (XP) που εξαργυρώνονται μόνο στο δικό σας μαγαζί, οπότε έχει λόγο να ξαναέρθει • Βλέπετε ποιος έρχεται, πόσο συχνά και τι παίρνει • Δεν αλλάζει τίποτα στο ταμείο: ίδιο POS, 0% προμήθεια, το στήνουμε εμείς σε 10 λεπτά • Δωρεάν προβολή στα TikTok/Instagram της Anbit και στον χάρτη της Anbit Θα σας ενδιέφερε να σας το δείξουμε από κοντά σε 10 λεπτά, όποτε σας βολεύει;
A12: 8 | B12: Branch | C12: @branch.athens | D12: Άνοιγμα | E12: Μήνυμα | F12: Αθήνα | G12: Πανόρμου | H12: All-day Cafe-Bar-Restaurant | I12: A | J12: Brunch, lunch, dinner, cocktails | L12: Δεν στάλθηκε | N12: =IF(M12="","",M12+4) | P12: =SUBSTITUTE(SUBSTITUTE(IF(I12="A",Μηνύματα!$B$7,Μηνύματα!$B$8),"{ΚΑΤΑΣΤΗΜΑ}",B12),"{ΟΝΟΜΑ}",Μηνύματα!$B$4) -> Γεια σας! 👋 Είμαι ο/η [Το όνομά σου] από την Anbit (anbit.gr). Μας άρεσε πολύ το Branch και θα θέλαμε να σας προτείνουμε μια συνεργασία. Η Anbit είναι παραγγελία από το τραπέζι με QR + σύστημα επιβράβευσης πελατών: • Ο πελάτης σκανάρει το QR, βλέπει το μενού με φωτογραφίες (Ελληνικά/Αγγλικά) και παραγγέλνει, χωρίς εφαρμογή • Η παραγγελία έρχεται στο κινητό ή στο tablet σας με τον αριθμό τραπεζιού • Με κάθε παραγγελία μαζεύει πόντους (XP) που εξαργυρώνονται μόνο στο δικό σας μαγαζί, οπότε έχει λόγο να ξαναέρθει • Βλέπετε ποιος έρχεται, πόσο συχνά και τι παίρνει • Δεν αλλάζει τίποτα στο ταμείο: ίδιο POS, 0% προμήθεια, το στήνουμε εμείς σε 10 λεπτά • Δωρεάν προβολή στα TikTok/Instagram της Anbit και στον χάρτη της Anbit Θα σας ενδιέφερε να σας το δείξουμε από κοντά σε 10 λεπτά, όποτε σας βολεύει;
A13: 9 | B13: Braziliana | C13: @brazilianabar | D13: Άνοιγμα | E13: Μήνυμα | F13: Αθήνα | G13: Άνω Πετράλωνα (Αρκάδων 4) | H13: All-day Bar | I13: A | L13: Δεν στάλθηκε | N13: =IF(M13="","",M13+4) | P13: =SUBSTITUTE(SUBSTITUTE(IF(I13="A",Μηνύματα!$B$7,Μηνύματα!$B$8),"{ΚΑΤΑΣΤΗΜΑ}",B13),"{ΟΝΟΜΑ}",Μηνύματα!$B$4) -> Γεια σας! 👋 Είμαι ο/η [Το όνομά σου] από την Anbit (anbit.gr). Μας άρεσε πολύ το Braziliana και θα θέλαμε να σας προτείνουμε μια συνεργασία. Η Anbit είναι παραγγελία από το τραπέζι με QR + σύστημα επιβράβευσης πελατών: • Ο πελάτης σκανάρει το QR, βλέπει το μενού με φωτογραφίες (Ελληνικά/Αγγλικά) και παραγγέλνει, χωρίς εφαρμογή • Η παραγγελία έρχεται στο κινητό ή στο tablet σας με τον αριθμό τραπεζιού • Με κάθε παραγγελία μαζεύει πόντους (XP) που εξαργυρώνονται μόνο στο δικό σας μαγαζί, οπότε έχει λόγο να ξαναέρθει • Βλέπετε ποιος έρχεται, πόσο συχνά και τι παίρνει • Δεν αλλάζει τίποτα στο ταμείο: ίδιο POS, 0% προμήθεια, το στήνουμε εμείς σε 10 λεπτά • Δωρεάν προβολή στα TikTok/Instagram της Anbit και στον χάρτη της Anbit Θα σας ενδιέφερε να σας το δείξουμε από κοντά σε 10 λεπτά, όποτε σας βολεύει;
A14: 10 | B14: Bunkok | C14: @bunkok.glyfada | D14: Άνοιγμα | E14: Μήνυμα | F14: Αθήνα | G14: Γλυφάδα | H14: Bakery-Brunch-Coffee | I14: A | J14: 07:00-20:00 καθημερινά | L14: Δεν στάλθηκε | N14: =IF(M14="","",M14+4) | P14: =SUBSTITUTE(SUBSTITUTE(IF(I14="A",Μηνύματα!$B$7,Μηνύματα!$B$8),"{ΚΑΤΑΣΤΗΜΑ}",B14),"{ΟΝΟΜΑ}",Μηνύματα!$B$4) -> Γεια σας! 👋 Είμαι ο/η [Το όνομά σου] από την Anbit (anbit.gr). Μας άρεσε πολύ το Bunkok και θα θέλαμε να σας προτείνουμε μια συνεργασία. Η Anbit είναι παραγγελία από το τραπέζι με QR + σύστημα επιβράβευσης πελατών: • Ο πελάτης σκανάρει το QR, βλέπει το μενού με φωτογραφίες (Ελληνικά/Αγγλικά) και παραγγέλνει, χωρίς εφαρμογή • Η παραγγελία έρχεται στο κινητό ή στο tablet σας με τον αριθμό τραπεζιού • Με κάθε παραγγελία μαζεύει πόντους (XP) που εξαργυρώνονται μόνο στο δικό σας μαγαζί, οπότε έχει λόγο να ξαναέρθει • Βλέπετε ποιος έρχεται, πόσο συχνά και τι παίρνει • Δεν αλλάζει τίποτα στο ταμείο: ίδιο POS, 0% προμήθεια, το στήνουμε εμείς σε 10 λεπτά • Δωρεάν προβολή στα TikTok/Instagram της Anbit και στον χάρτη της Anbit Θα σας ενδιέφερε να σας το δείξουμε από κοντά σε 10 λεπτά, όποτε σας βολεύει;
A15: 11 | B15: Coco Cafe | C15: @cococafebeat | D15: Άνοιγμα | E15: Μήνυμα | F15: Αθήνα | G15: Κυψέλη (Βελβενδού 46) | H15: Cafe / Κρέπες | I15: A | L15: Δεν στάλθηκε | N15: =IF(M15="","",M15+4) | P15: =SUBSTITUTE(SUBSTITUTE(IF(I15="A",Μηνύματα!$B$7,Μηνύματα!$B$8),"{ΚΑΤΑΣΤΗΜΑ}",B15),"{ΟΝΟΜΑ}",Μηνύματα!$B$4) -> Γεια σας! 👋 Είμαι ο/η [Το όνομά σου] από την Anbit (anbit.gr). Μας άρεσε πολύ το Coco Cafe και θα θέλαμε να σας προτείνουμε μια συνεργασία. Η Anbit είναι παραγγελία από το τραπέζι με QR + σύστημα επιβράβευσης πελατών: • Ο πελάτης σκανάρει το QR, βλέπει το μενού με φωτογραφίες (Ελληνικά/Αγγλικά) και παραγγέλνει, χωρίς εφαρμογή • Η παραγγελία έρχεται στο κινητό ή στο tablet σας με τον αριθμό τραπεζιού • Με κάθε παραγγελία μαζεύει πόντους (XP) που εξαργυρώνονται μόνο στο δικό σας μαγαζί, οπότε έχει λόγο να ξαναέρθει • Βλέπετε ποιος έρχεται, πόσο συχνά και τι παίρνει • Δεν αλλάζει τίποτα στο ταμείο: ίδιο POS, 0% προμήθεια, το στήνουμε εμείς σε 10 λεπτά • Δωρεάν προβολή στα TikTok/Instagram της Anbit και στον χάρτη της Anbit Θα σας ενδιέφερε να σας το δείξουμε από κοντά σε 10 λεπτά, όποτε σας βολεύει;
A16: 12 | B16: Coffee N Roses | C16: @coffeenroses_ | D16: Άνοιγμα | E16: Μήνυμα | F16: Αθήνα | G16: Π. Φάληρο (Παρθενώνος 43) | H16: Coffee | I16: A | J16: Παραγγελίες 216 9008380 | L16: Δεν στάλθηκε | N16: =IF(M16="","",M16+4) | P16: =SUBSTITUTE(SUBSTITUTE(IF(I16="A",Μηνύματα!$B$7,Μηνύματα!$B$8),"{ΚΑΤΑΣΤΗΜΑ}",B16),"{ΟΝΟΜΑ}",Μηνύματα!$B$4) -> Γεια σας! 👋 Είμαι ο/η [Το όνομά σου] από την Anbit (anbit.gr). Μας άρεσε πολύ το Coffee N Roses και θα θέλαμε να σας προτείνουμε μια συνεργασία. Η Anbit είναι παραγγελία από το τραπέζι με QR + σύστημα επιβράβευσης πελατών: • Ο πελάτης σκανάρει το QR, βλέπει το μενού με φωτογραφίες (Ελληνικά/Αγγλικά) και παραγγέλνει, χωρίς εφαρμογή • Η παραγγελία έρχεται στο κινητό ή στο tablet σας με τον αριθμό τραπεζιού • Με κάθε παραγγελία μαζεύει πόντους (XP) που εξαργυρώνονται μόνο στο δικό σας μαγαζί, οπότε έχει λόγο να ξαναέρθει • Βλέπετε ποιος έρχεται, πόσο συχνά και τι παίρνει • Δεν αλλάζει τίποτα στο ταμείο: ίδιο POS, 0% προμήθεια, το στήνουμε εμείς σε 10 λεπτά • Δωρεάν προβολή στα TikTok/Instagram της Anbit και στον χάρτη της Anbit Θα σας ενδιέφερε να σας το δείξουμε από κοντά σε 10 λεπτά, όποτε σας βολεύει;
A17: 13 | B17: Colonial Glyfada | C17: @colonialglyfada | D17: Άνοιγμα | E17: Μήνυμα | F17: Αθήνα | G17: Γλυφάδα (Golf) | H17: All-day Cafe-Restaurant | I17: A | J17: Από 08:00 καθημερινά | L17: Δεν στάλθηκε | N17: =IF(M17="","",M17+4) | P17: =SUBSTITUTE(SUBSTITUTE(IF(I17="A",Μηνύματα!$B$7,Μηνύματα!$B$8),"{ΚΑΤΑΣΤΗΜΑ}",B17),"{ΟΝΟΜΑ}",Μηνύματα!$B$4) -> Γεια σας! 👋 Είμαι ο/η [Το όνομά σου] από την Anbit (anbit.gr). Μας άρεσε πολύ το Colonial Glyfada και θα θέλαμε να σας προτείνουμε μια συνεργασία. Η Anbit είναι παραγγελία από το τραπέζι με QR + σύστημα επιβράβευσης πελατών: • Ο πελάτης σκανάρει το QR, βλέπει το μενού με φωτογραφίες (Ελληνικά/Αγγλικά) και παραγγέλνει, χωρίς εφαρμογή • Η παραγγελία έρχεται στο κινητό ή στο tablet σας με τον αριθμό τραπεζιού • Με κάθε παραγγελία μαζεύει πόντους (XP) που εξαργυρώνονται μόνο στο δικό σας μαγαζί, οπότε έχει λόγο να ξαναέρθει • Βλέπετε ποιος έρχεται, πόσο συχνά και τι παίρνει • Δεν αλλάζει τίποτα στο ταμείο: ίδιο POS, 0% προμήθεια, το στήνουμε εμείς σε 10 λεπτά • Δωρεάν προβολή στα TikTok/Instagram της Anbit και στον χάρτη της Anbit Θα σας ενδιέφερε να σας το δείξουμε από κοντά σε 10 λεπτά, όποτε σας βολεύει;
A18: 14 | B18: El Sito Coffee Bar | C18: @el_sito_coffeebar | D18: Άνοιγμα | E18: Μήνυμα | F18: Αθήνα | G18: Γλυφάδα | H18: Coffee Bar | I18: A | K18: Επιβεβαίωσε περιοχή | L18: Δεν στάλθηκε | N18: =IF(M18="","",M18+4) | P18: =SUBSTITUTE(SUBSTITUTE(IF(I18="A",Μηνύματα!$B$7,Μηνύματα!$B$8),"{ΚΑΤΑΣΤΗΜΑ}",B18),"{ΟΝΟΜΑ}",Μηνύματα!$B$4) -> Γεια σας! 👋 Είμαι ο/η [Το όνομά σου] από την Anbit (anbit.gr). Μας άρεσε πολύ το El Sito Coffee Bar και θα θέλαμε να σας προτείνουμε μια συνεργασία. Η Anbit είναι παραγγελία από το τραπέζι με QR + σύστημα επιβράβευσης πελατών: • Ο πελάτης σκανάρει το QR, βλέπει το μενού με φωτογραφίες (Ελληνικά/Αγγλικά) και παραγγέλνει, χωρίς εφαρμογή • Η παραγγελία έρχεται στο κινητό ή στο tablet σας με τον αριθμό τραπεζιού • Με κάθε παραγγελία μαζεύει πόντους (XP) που εξαργυρώνονται μόνο στο δικό σας μαγαζί, οπότε έχει λόγο να ξαναέρθει • Βλέπετε ποιος έρχεται, πόσο συχνά και τι παίρνει • Δεν αλλάζει τίποτα στο ταμείο: ίδιο POS, 0% προμήθεια, το στήνουμε εμείς σε 10 λεπτά • Δωρεάν προβολή στα TikTok/Instagram της Anbit και στον χάρτη της Anbit Θα σας ενδιέφερε να σας το δείξουμε από κοντά σε 10 λεπτά, όποτε σας βολεύει;
A19: 15 | B19: Espressaki Café Bistro | C19: @espressakicafebistro | D19: Άνοιγμα | E19: Μήνυμα | F19: Αθήνα | H19: Cafe-Bistro / Cocktails | I19: A | J19: Σπιτικά γλυκά | K19: Επιβεβαίωσε περιοχή | L19: Δεν στάλθηκε | N19: =IF(M19="","",M19+4) | P19: =SUBSTITUTE(SUBSTITUTE(IF(I19="A",Μηνύματα!$B$7,Μηνύματα!$B$8),"{ΚΑΤΑΣΤΗΜΑ}",B19),"{ΟΝΟΜΑ}",Μηνύματα!$B$4) -> Γεια σας! 👋 Είμαι ο/η [Το όνομά σου] από την Anbit (anbit.gr). Μας άρεσε πολύ το Espressaki Café Bistro και θα θέλαμε να σας προτείνουμε μια συνεργασία. Η Anbit είναι παραγγελία από το τραπέζι με QR + σύστημα επιβράβευσης πελατών: • Ο πελάτης σκανάρει το QR, βλέπει το μενού με φωτογραφίες (Ελληνικά/Αγγλικά) και παραγγέλνει, χωρίς εφαρμογή • Η παραγγελία έρχεται στο κινητό ή στο tablet σας με τον αριθμό τραπεζιού • Με κάθε παραγγελία μαζεύει πόντους (XP) που εξαργυρώνονται μόνο στο δικό σας μαγαζί, οπότε έχει λόγο να ξαναέρθει • Βλέπετε ποιος έρχεται, πόσο συχνά και τι παίρνει • Δεν αλλάζει τίποτα στο ταμείο: ίδιο POS, 0% προμήθεια, το στήνουμε εμείς σε 10 λεπτά • Δωρεάν προβολή στα TikTok/Instagram της Anbit και στον χάρτη της Anbit Θα σας ενδιέφερε να σας το δείξουμε από κοντά σε 10 λεπτά, όποτε σας βολεύει;
A20: 16 | B20: Favela All Day Bar Restaurant | C20: @favela_all_day_bar_restaurant | D20: Άνοιγμα | E20: Μήνυμα | F20: Αθήνα | H20: All-day Bar-Restaurant | I20: A | K20: Επιβεβαίωσε περιοχή | L20: Δεν στάλθηκε | N20: =IF(M20="","",M20+4) | P20: =SUBSTITUTE(SUBSTITUTE(IF(I20="A",Μηνύματα!$B$7,Μηνύματα!$B$8),"{ΚΑΤΑΣΤΗΜΑ}",B20),"{ΟΝΟΜΑ}",Μηνύματα!$B$4) -> Γεια σας! 👋 Είμαι ο/η [Το όνομά σου] από την Anbit (anbit.gr). Μας άρεσε πολύ το Favela All Day Bar Restaurant και θα θέλαμε να σας προτείνουμε μια συνεργασία. Η Anbit είναι παραγγελία από το τραπέζι με QR + σύστημα επιβράβευσης πελατών: • Ο πελάτης σκανάρει το QR, βλέπει το μενού με φωτογραφίες (Ελληνικά/Αγγλικά) και παραγγέλνει, χωρίς εφαρμογή • Η παραγγελία έρχεται στο κινητό ή στο tablet σας με τον αριθμό τραπεζιού • Με κάθε παραγγελία μαζεύει πόντους (XP) που εξαργυρώνονται μόνο στο δικό σας μαγαζί, οπότε έχει λόγο να ξαναέρθει • Βλέπετε ποιος έρχεται, πόσο συχνά και τι παίρνει • Δεν αλλάζει τίποτα στο ταμείο: ίδιο POS, 0% προμήθεια, το στήνουμε εμείς σε 10 λεπτά • Δωρεάν προβολή στα TikTok/Instagram της Anbit και στον χάρτη της Anbit Θα σας ενδιέφερε να σας το δείξουμε από κοντά σε 10 λεπτά, όποτε σας βολεύει;
A21: 17 | B21: Flavour Business Resto Cafe | C21: @flavour.athens | D21: Άνοιγμα | E21: Μήνυμα | F21: Αθήνα | H21: Resto Cafe | I21: A | J21: 07:00-02:00 καθημερινά | K21: Επιβεβαίωσε περιοχή | L21: Δεν στάλθηκε | N21: =IF(M21="","",M21+4) | P21: =SUBSTITUTE(SUBSTITUTE(IF(I21="A",Μηνύματα!$B$7,Μηνύματα!$B$8),"{ΚΑΤΑΣΤΗΜΑ}",B21),"{ΟΝΟΜΑ}",Μηνύματα!$B$4) -> Γεια σας! 👋 Είμαι ο/η [Το όνομά σου] από την Anbit (anbit.gr). Μας άρεσε πολύ το Flavour Business Resto Cafe και θα θέλαμε να σας προτείνουμε μια συνεργασία. Η Anbit είναι παραγγελία από το τραπέζι με QR + σύστημα επιβράβευσης πελατών: • Ο πελάτης σκανάρει το QR, βλέπει το μενού με φωτογραφίες (Ελληνικά/Αγγλικά) και παραγγέλνει, χωρίς εφαρμογή • Η παραγγελία έρχεται στο κινητό ή στο tablet σας με τον αριθμό τραπεζιού • Με κάθε παραγγελία μαζεύει πόντους (XP) που εξαργυρώνονται μόνο στο δικό σας μαγαζί, οπότε έχει λόγο να ξαναέρθει • Βλέπετε ποιος έρχεται, πόσο συχνά και τι παίρνει • Δεν αλλάζει τίποτα στο ταμείο: ίδιο POS, 0% προμήθεια, το στήνουμε εμείς σε 10 λεπτά • Δωρεάν προβολή στα TikTok/Instagram της Anbit και στον χάρτη της Anbit Θα σας ενδιέφερε να σας το δείξουμε από κοντά σε 10 λεπτά, όποτε σας βολεύει;
A22: 18 | B22: G Cafe Bar | C22: @gcafebar | D22: Άνοιγμα | E22: Μήνυμα | F22: Αθήνα | H22: Cafe-Bar | I22: A | K22: Επιβεβαίωσε περιοχή | L22: Δεν στάλθηκε | N22: =IF(M22="","",M22+4) | P22: =SUBSTITUTE(SUBSTITUTE(IF(I22="A",Μηνύματα!$B$7,Μηνύματα!$B$8),"{ΚΑΤΑΣΤΗΜΑ}",B22),"{ΟΝΟΜΑ}",Μηνύματα!$B$4) -> Γεια σας! 👋 Είμαι ο/η [Το όνομά σου] από την Anbit (anbit.gr). Μας άρεσε πολύ το G Cafe Bar και θα θέλαμε να σας προτείνουμε μια συνεργασία. Η Anbit είναι παραγγελία από το τραπέζι με QR + σύστημα επιβράβευσης πελατών: • Ο πελάτης σκανάρει το QR, βλέπει το μενού με φωτογραφίες (Ελληνικά/Αγγλικά) και παραγγέλνει, χωρίς εφαρμογή • Η παραγγελία έρχεται στο κινητό ή στο tablet σας με τον αριθμό τραπεζιού • Με κάθε παραγγελία μαζεύει πόντους (XP) που εξαργυρώνονται μόνο στο δικό σας μαγαζί, οπότε έχει λόγο να ξαναέρθει • Βλέπετε ποιος έρχεται, πόσο συχνά και τι παίρνει • Δεν αλλάζει τίποτα στο ταμείο: ίδιο POS, 0% προμήθεια, το στήνουμε εμείς σε 10 λεπτά • Δωρεάν προβολή στα TikTok/Instagram της Anbit και στον χάρτη της Anbit Θα σας ενδιέφερε να σας το δείξουμε από κοντά σε 10 λεπτά, όποτε σας βολεύει;
A23: 19 | B23: Genesis Coffee Spot | C23: @genesis.athens | D23: Άνοιγμα | E23: Μήνυμα | F23: Αθήνα | G23: Παγκράτι (Ευφράνορος) | H23: Coffee | I23: A | J23: Νέο/μικρό προφίλ, efood & Wolt | L23: Δεν στάλθηκε | N23: =IF(M23="","",M23+4) | P23: =SUBSTITUTE(SUBSTITUTE(IF(I23="A",Μηνύματα!$B$7,Μηνύματα!$B$8),"{ΚΑΤΑΣΤΗΜΑ}",B23),"{ΟΝΟΜΑ}",Μηνύματα!$B$4) -> Γεια σας! 👋 Είμαι ο/η [Το όνομά σου] από την Anbit (anbit.gr). Μας άρεσε πολύ το Genesis Coffee Spot και θα θέλαμε να σας προτείνουμε μια συνεργασία. Η Anbit είναι παραγγελία από το τραπέζι με QR + σύστημα επιβράβευσης πελατών: • Ο πελάτης σκανάρει το QR, βλέπει το μενού με φωτογραφίες (Ελληνικά/Αγγλικά) και παραγγέλνει, χωρίς εφαρμογή • Η παραγγελία έρχεται στο κινητό ή στο tablet σας με τον αριθμό τραπεζιού • Με κάθε παραγγελία μαζεύει πόντους (XP) που εξαργυρώνονται μόνο στο δικό σας μαγαζί, οπότε έχει λόγο να ξαναέρθει • Βλέπετε ποιος έρχεται, πόσο συχνά και τι παίρνει • Δεν αλλάζει τίποτα στο ταμείο: ίδιο POS, 0% προμήθεια, το στήνουμε εμείς σε 10 λεπτά • Δωρεάν προβολή στα TikTok/Instagram της Anbit και στον χάρτη της Anbit Θα σας ενδιέφερε να σας το δείξουμε από κοντά σε 10 λεπτά, όποτε σας βολεύει;
A24: 20 | B24: HUUS Kaffe Fokionos | C24: @huus_fokionos | D24: Άνοιγμα | E24: Μήνυμα | F24: Αθήνα | G24: Κυψέλη | H24: Specialty Coffee | I24: A | J24: Specialty καφές & χειροποίητα κρουασάν, έχει κι άλλα καταστήματα | L24: Δεν στάλθηκε | N24: =IF(M24="","",M24+4) | P24: =SUBSTITUTE(SUBSTITUTE(IF(I24="A",Μηνύματα!$B$7,Μηνύματα!$B$8),"{ΚΑΤΑΣΤΗΜΑ}",B24),"{ΟΝΟΜΑ}",Μηνύματα!$B$4) -> Γεια σας! 👋 Είμαι ο/η [Το όνομά σου] από την Anbit (anbit.gr). Μας άρεσε πολύ το HUUS Kaffe Fokionos και θα θέλαμε να σας προτείνουμε μια συνεργασία. Η Anbit είναι παραγγελία από το τραπέζι με QR + σύστημα επιβράβευσης πελατών: • Ο πελάτης σκανάρει το QR, βλέπει το μενού με φωτογραφίες (Ελληνικά/Αγγλικά) και παραγγέλνει, χωρίς εφαρμογή • Η παραγγελία έρχεται στο κινητό ή στο tablet σας με τον αριθμό τραπεζιού • Με κάθε παραγγελία μαζεύει πόντους (XP) που εξαργυρώνονται μόνο στο δικό σας μαγαζί, οπότε έχει λόγο να ξαναέρθει • Βλέπετε ποιος έρχεται, πόσο συχνά και τι παίρνει • Δεν αλλάζει τίποτα στο ταμείο: ίδιο POS, 0% προμήθεια, το στήνουμε εμείς σε 10 λεπτά • Δωρεάν προβολή στα TikTok/Instagram της Anbit και στον χάρτη της Anbit Θα σας ενδιέφερε να σας το δείξουμε από κοντά σε 10 λεπτά, όποτε σας βολεύει;
A25: 21 | B25: I Cafe Bar | C25: @icafebar | D25: Άνοιγμα | E25: Μήνυμα | F25: Αθήνα | G25: Αργυρούπολη | H25: All-day Cafe-Bar | I25: A | L25: Δεν στάλθηκε | N25: =IF(M25="","",M25+4) | P25: =SUBSTITUTE(SUBSTITUTE(IF(I25="A",Μηνύματα!$B$7,Μηνύματα!$B$8),"{ΚΑΤΑΣΤΗΜΑ}",B25),"{ΟΝΟΜΑ}",Μηνύματα!$B$4) -> Γεια σας! 👋 Είμαι ο/η [Το όνομά σου] από την Anbit (anbit.gr). Μας άρεσε πολύ το I Cafe Bar και θα θέλαμε να σας προτείνουμε μια συνεργασία. Η Anbit είναι παραγγελία από το τραπέζι με QR + σύστημα επιβράβευσης πελατών: • Ο πελάτης σκανάρει το QR, βλέπει το μενού με φωτογραφίες (Ελληνικά/Αγγλικά) και παραγγέλνει, χωρίς εφαρμογή • Η παραγγελία έρχεται στο κινητό ή στο tablet σας με τον αριθμό τραπεζιού • Με κάθε παραγγελία μαζεύει πόντους (XP) που εξαργυρώνονται μόνο στο δικό σας μαγαζί, οπότε έχει λόγο να ξαναέρθει • Βλέπετε ποιος έρχεται, πόσο συχνά και τι παίρνει • Δεν αλλάζει τίποτα στο ταμείο: ίδιο POS, 0% προμήθεια, το στήνουμε εμείς σε 10 λεπτά • Δωρεάν προβολή στα TikTok/Instagram της Anbit και στον χάρτη της Anbit Θα σας ενδιέφερε να σας το δείξουμε από κοντά σε 10 λεπτά, όποτε σας βολεύει;
A26: 22 | B26: JOJO espresso & bar | C26: @jojoperisteri | D26: Άνοιγμα | E26: Μήνυμα | F26: Αθήνα | G26: Μπουρνάζι (Αγ. Παρασκευής) | H26: Coffee & Bar | I26: A | L26: Δεν στάλθηκε | N26: =IF(M26="","",M26+4) | P26: =SUBSTITUTE(SUBSTITUTE(IF(I26="A",Μηνύματα!$B$7,Μηνύματα!$B$8),"{ΚΑΤΑΣΤΗΜΑ}",B26),"{ΟΝΟΜΑ}",Μηνύματα!$B$4) -> Γεια σας! 👋 Είμαι ο/η [Το όνομά σου] από την Anbit (anbit.gr). Μας άρεσε πολύ το JOJO espresso & bar και θα θέλαμε να σας προτείνουμε μια συνεργασία. Η Anbit είναι παραγγελία από το τραπέζι με QR + σύστημα επιβράβευσης πελατών: • Ο πελάτης σκανάρει το QR, βλέπει το μενού με φωτογραφίες (Ελληνικά/Αγγλικά) και παραγγέλνει, χωρίς εφαρμογή • Η παραγγελία έρχεται στο κινητό ή στο tablet σας με τον αριθμό τραπεζιού • Με κάθε παραγγελία μαζεύει πόντους (XP) που εξαργυρώνονται μόνο στο δικό σας μαγαζί, οπότε έχει λόγο να ξαναέρθει • Βλέπετε ποιος έρχεται, πόσο συχνά και τι παίρνει • Δεν αλλάζει τίποτα στο ταμείο: ίδιο POS, 0% προμήθεια, το στήνουμε εμείς σε 10 λεπτά • Δωρεάν προβολή στα TikTok/Instagram της Anbit και στον χάρτη της Anbit Θα σας ενδιέφερε να σας το δείξουμε από κοντά σε 10 λεπτά, όποτε σας βολεύει;
A27: 23 | B27: Kalimeres Bistro | C27: @kalimeres.bistro | D27: Άνοιγμα | E27: Μήνυμα | F27: Αθήνα | H27: Bistro / Brunch | I27: A | K27: Επιβεβαίωσε περιοχή | L27: Δεν στάλθηκε | N27: =IF(M27="","",M27+4) | P27: =SUBSTITUTE(SUBSTITUTE(IF(I27="A",Μηνύματα!$B$7,Μηνύματα!$B$8),"{ΚΑΤΑΣΤΗΜΑ}",B27),"{ΟΝΟΜΑ}",Μηνύματα!$B$4) -> Γεια σας! 👋 Είμαι ο/η [Το όνομά σου] από την Anbit (anbit.gr). Μας άρεσε πολύ το Kalimeres Bistro και θα θέλαμε να σας προτείνουμε μια συνεργασία. Η Anbit είναι παραγγελία από το τραπέζι με QR + σύστημα επιβράβευσης πελατών: • Ο πελάτης σκανάρει το QR, βλέπει το μενού με φωτογραφίες (Ελληνικά/Αγγλικά) και παραγγέλνει, χωρίς εφαρμογή • Η παραγγελία έρχεται στο κινητό ή στο tablet σας με τον αριθμό τραπεζιού • Με κάθε παραγγελία μαζεύει πόντους (XP) που εξαργυρώνονται μόνο στο δικό σας μαγαζί, οπότε έχει λόγο να ξαναέρθει • Βλέπετε ποιος έρχεται, πόσο συχνά και τι παίρνει • Δεν αλλάζει τίποτα στο ταμείο: ίδιο POS, 0% προμήθεια, το στήνουμε εμείς σε 10 λεπτά • Δωρεάν προβολή στα TikTok/Instagram της Anbit και στον χάρτη της Anbit Θα σας ενδιέφερε να σας το δείξουμε από κοντά σε 10 λεπτά, όποτε σας βολεύει;
A28: 24 | B28: Korne | C28: @korne.gr | D28: Άνοιγμα | E28: Μήνυμα | F28: Αθήνα | G28: Νέα Ιωνία (Ελ. Βενιζέλου 128) | H28: Bakery-Cafe | I28: A | J28: Τηλ. 211 4104918, νέο κατάστημα | L28: Δεν στάλθηκε | N28: =IF(M28="","",M28+4) | P28: =SUBSTITUTE(SUBSTITUTE(IF(I28="A",Μηνύματα!$B$7,Μηνύματα!$B$8),"{ΚΑΤΑΣΤΗΜΑ}",B28),"{ΟΝΟΜΑ}",Μηνύματα!$B$4) -> Γεια σας! 👋 Είμαι ο/η [Το όνομά σου] από την Anbit (anbit.gr). Μας άρεσε πολύ το Korne και θα θέλαμε να σας προτείνουμε μια συνεργασία. Η Anbit είναι παραγγελία από το τραπέζι με QR + σύστημα επιβράβευσης πελατών: • Ο πελάτης σκανάρει το QR, βλέπει το μενού με φωτογραφίες (Ελληνικά/Αγγλικά) και παραγγέλνει, χωρίς εφαρμογή • Η παραγγελία έρχεται στο κινητό ή στο tablet σας με τον αριθμό τραπεζιού • Με κάθε παραγγελία μαζεύει πόντους (XP) που εξαργυρώνονται μόνο στο δικό σας μαγαζί, οπότε έχει λόγο να ξαναέρθει • Βλέπετε ποιος έρχεται, πόσο συχνά και τι παίρνει • Δεν αλλάζει τίποτα στο ταμείο: ίδιο POS, 0% προμήθεια, το στήνουμε εμείς σε 10 λεπτά • Δωρεάν προβολή στα TikTok/Instagram της Anbit και στον χάρτη της Anbit Θα σας ενδιέφερε να σας το δείξουμε από κοντά σε 10 λεπτά, όποτε σας βολεύει;
A29: 25 | B29: Kupato | C29: @kupato_official | D29: Άνοιγμα | E29: Μήνυμα | F29: Αθήνα | G29: Μαρούσι (Αγ. Κωνσταντίνου 53) | H29: Specialty Coffee / Brunch | I29: A | J29: Brunch by chef | L29: Δεν στάλθηκε | N29: =IF(M29="","",M29+4) | P29: =SUBSTITUTE(SUBSTITUTE(IF(I29="A",Μηνύματα!$B$7,Μηνύματα!$B$8),"{ΚΑΤΑΣΤΗΜΑ}",B29),"{ΟΝΟΜΑ}",Μηνύματα!$B$4) -> Γεια σας! 👋 Είμαι ο/η [Το όνομά σου] από την Anbit (anbit.gr). Μας άρεσε πολύ το Kupato και θα θέλαμε να σας προτείνουμε μια συνεργασία. Η Anbit είναι παραγγελία από το τραπέζι με QR + σύστημα επιβράβευσης πελατών: • Ο πελάτης σκανάρει το QR, βλέπει το μενού με φωτογραφίες (Ελληνικά/Αγγλικά) και παραγγέλνει, χωρίς εφαρμογή • Η παραγγελία έρχεται στο κινητό ή στο tablet σας με τον αριθμό τραπεζιού • Με κάθε παραγγελία μαζεύει πόντους (XP) που εξαργυρώνονται μόνο στο δικό σας μαγαζί, οπότε έχει λόγο να ξαναέρθει • Βλέπετε ποιος έρχεται, πόσο συχνά και τι παίρνει • Δεν αλλάζει τίποτα στο ταμείο: ίδιο POS, 0% προμήθεια, το στήνουμε εμείς σε 10 λεπτά • Δωρεάν προβολή στα TikTok/Instagram της Anbit και στον χάρτη της Anbit Θα σας ενδιέφερε να σας το δείξουμε από κοντά σε 10 λεπτά, όποτε σας βολεύει;
A30: 26 | B30: Level Up Specialty Coffee | C30: @level.up.marousi | D30: Άνοιγμα | E30: Μήνυμα | F30: Αθήνα | G30: Μαρούσι | H30: Specialty Coffee | I30: A | J30: 07:30-20:00, efood & Box | L30: Δεν στάλθηκε | N30: =IF(M30="","",M30+4) | P30: =SUBSTITUTE(SUBSTITUTE(IF(I30="A",Μηνύματα!$B$7,Μηνύματα!$B$8),"{ΚΑΤΑΣΤΗΜΑ}",B30),"{ΟΝΟΜΑ}",Μηνύματα!$B$4) -> Γεια σας! 👋 Είμαι ο/η [Το όνομά σου] από την Anbit (anbit.gr). Μας άρεσε πολύ το Level Up Specialty Coffee και θα θέλαμε να σας προτείνουμε μια συνεργασία. Η Anbit είναι παραγγελία από το τραπέζι με QR + σύστημα επιβράβευσης πελατών: • Ο πελάτης σκανάρει το QR, βλέπει το μενού με φωτογραφίες (Ελληνικά/Αγγλικά) και παραγγέλνει, χωρίς εφαρμογή • Η παραγγελία έρχεται στο κινητό ή στο tablet σας με τον αριθμό τραπεζιού • Με κάθε παραγγελία μαζεύει πόντους (XP) που εξαργυρώνονται μόνο στο δικό σας μαγαζί, οπότε έχει λόγο να ξαναέρθει • Βλέπετε ποιος έρχεται, πόσο συχνά και τι παίρνει • Δεν αλλάζει τίποτα στο ταμείο: ίδιο POS, 0% προμήθεια, το στήνουμε εμείς σε 10 λεπτά • Δωρεάν προβολή στα TikTok/Instagram της Anbit και στον χάρτη της Anbit Θα σας ενδιέφερε να σας το δείξουμε από κοντά σε 10 λεπτά, όποτε σας βολεύει;
A31: 27 | B31: LIBERTY Cafè Bar | C31: @liberty_cafebar | D31: Άνοιγμα | E31: Μήνυμα | F31: Αθήνα | G31: Πειραιάς (Παλαιολόγου 5, Τερψιθέα) | H31: Cafe-Wine-Cocktail bar | I31: A | L31: Δεν στάλθηκε | N31: =IF(M31="","",M31+4) | P31: =SUBSTITUTE(SUBSTITUTE(IF(I31="A",Μηνύματα!$B$7,Μηνύματα!$B$8),"{ΚΑΤΑΣΤΗΜΑ}",B31),"{ΟΝΟΜΑ}",Μηνύματα!$B$4) -> Γεια σας! 👋 Είμαι ο/η [Το όνομά σου] από την Anbit (anbit.gr). Μας άρεσε πολύ το LIBERTY Cafè Bar και θα θέλαμε να σας προτείνουμε μια συνεργασία. Η Anbit είναι παραγγελία από το τραπέζι με QR + σύστημα επιβράβευσης πελατών: • Ο πελάτης σκανάρει το QR, βλέπει το μενού με φωτογραφίες (Ελληνικά/Αγγλικά) και παραγγέλνει, χωρίς εφαρμογή • Η παραγγελία έρχεται στο κινητό ή στο tablet σας με τον αριθμό τραπεζιού • Με κάθε παραγγελία μαζεύει πόντους (XP) που εξαργυρώνονται μόνο στο δικό σας μαγαζί, οπότε έχει λόγο να ξαναέρθει • Βλέπετε ποιος έρχεται, πόσο συχνά και τι παίρνει • Δεν αλλάζει τίποτα στο ταμείο: ίδιο POS, 0% προμήθεια, το στήνουμε εμείς σε 10 λεπτά • Δωρεάν προβολή στα TikTok/Instagram της Anbit και στον χάρτη της Anbit Θα σας ενδιέφερε να σας το δείξουμε από κοντά σε 10 λεπτά, όποτε σας βολεύει;
A32: 28 | B32: Local Cafe-Bar | C32: @local_cafebar | D32: Άνοιγμα | E32: Μήνυμα | F32: Αθήνα | G32: Ίλιον | H32: All-day Cafe-Bar | I32: A | J32: Brunch 09:00-14:00 | L32: Δεν στάλθηκε | N32: =IF(M32="","",M32+4) | P32: =SUBSTITUTE(SUBSTITUTE(IF(I32="A",Μηνύματα!$B$7,Μηνύματα!$B$8),"{ΚΑΤΑΣΤΗΜΑ}",B32),"{ΟΝΟΜΑ}",Μηνύματα!$B$4) -> Γεια σας! 👋 Είμαι ο/η [Το όνομά σου] από την Anbit (anbit.gr). Μας άρεσε πολύ το Local Cafe-Bar και θα θέλαμε να σας προτείνουμε μια συνεργασία. Η Anbit είναι παραγγελία από το τραπέζι με QR + σύστημα επιβράβευσης πελατών: • Ο πελάτης σκανάρει το QR, βλέπει το μενού με φωτογραφίες (Ελληνικά/Αγγλικά) και παραγγέλνει, χωρίς εφαρμογή • Η παραγγελία έρχεται στο κινητό ή στο tablet σας με τον αριθμό τραπεζιού • Με κάθε παραγγελία μαζεύει πόντους (XP) που εξαργυρώνονται μόνο στο δικό σας μαγαζί, οπότε έχει λόγο να ξαναέρθει • Βλέπετε ποιος έρχεται, πόσο συχνά και τι παίρνει • Δεν αλλάζει τίποτα στο ταμείο: ίδιο POS, 0% προμήθεια, το στήνουμε εμείς σε 10 λεπτά • Δωρεάν προβολή στα TikTok/Instagram της Anbit και στον χάρτη της Anbit Θα σας ενδιέφερε να σας το δείξουμε από κοντά σε 10 λεπτά, όποτε σας βολεύει;
A33: 29 | B33: Lola Cafe Bar | C33: @lolacafebar | D33: Άνοιγμα | E33: Μήνυμα | F33: Αθήνα | G33: Αγία Παρασκευή | H33: Cafe-Bar | I33: A | L33: Δεν στάλθηκε | N33: =IF(M33="","",M33+4) | P33: =SUBSTITUTE(SUBSTITUTE(IF(I33="A",Μηνύματα!$B$7,Μηνύματα!$B$8),"{ΚΑΤΑΣΤΗΜΑ}",B33),"{ΟΝΟΜΑ}",Μηνύματα!$B$4) -> Γεια σας! 👋 Είμαι ο/η [Το όνομά σου] από την Anbit (anbit.gr). Μας άρεσε πολύ το Lola Cafe Bar και θα θέλαμε να σας προτείνουμε μια συνεργασία. Η Anbit είναι παραγγελία από το τραπέζι με QR + σύστημα επιβράβευσης πελατών: • Ο πελάτης σκανάρει το QR, βλέπει το μενού με φωτογραφίες (Ελληνικά/Αγγλικά) και παραγγέλνει, χωρίς εφαρμογή • Η παραγγελία έρχεται στο κινητό ή στο tablet σας με τον αριθμό τραπεζιού • Με κάθε παραγγελία μαζεύει πόντους (XP) που εξαργυρώνονται μόνο στο δικό σας μαγαζί, οπότε έχει λόγο να ξαναέρθει • Βλέπετε ποιος έρχεται, πόσο συχνά και τι παίρνει • Δεν αλλάζει τίποτα στο ταμείο: ίδιο POS, 0% προμήθεια, το στήνουμε εμείς σε 10 λεπτά • Δωρεάν προβολή στα TikTok/Instagram της Anbit και στον χάρτη της Anbit Θα σας ενδιέφερε να σας το δείξουμε από κοντά σε 10 λεπτά, όποτε σας βολεύει;
A34: 30 | B34: Madeira Cafe & Bar | C34: @madeiraathens | D34: Άνοιγμα | E34: Μήνυμα | F34: Αθήνα | H34: Cafe-Cocktail bar | I34: A | J34: Live events | K34: Επιβεβαίωσε περιοχή | L34: Δεν στάλθηκε | N34: =IF(M34="","",M34+4) | P34: =SUBSTITUTE(SUBSTITUTE(IF(I34="A",Μηνύματα!$B$7,Μηνύματα!$B$8),"{ΚΑΤΑΣΤΗΜΑ}",B34),"{ΟΝΟΜΑ}",Μηνύματα!$B$4) -> Γεια σας! 👋 Είμαι ο/η [Το όνομά σου] από την Anbit (anbit.gr). Μας άρεσε πολύ το Madeira Cafe & Bar και θα θέλαμε να σας προτείνουμε μια συνεργασία. Η Anbit είναι παραγγελία από το τραπέζι με QR + σύστημα επιβράβευσης πελατών: • Ο πελάτης σκανάρει το QR, βλέπει το μενού με φωτογραφίες (Ελληνικά/Αγγλικά) και παραγγέλνει, χωρίς εφαρμογή • Η παραγγελία έρχεται στο κινητό ή στο tablet σας με τον αριθμό τραπεζιού • Με κάθε παραγγελία μαζεύει πόντους (XP) που εξαργυρώνονται μόνο στο δικό σας μαγαζί, οπότε έχει λόγο να ξαναέρθει • Βλέπετε ποιος έρχεται, πόσο συχνά και τι παίρνει • Δεν αλλάζει τίποτα στο ταμείο: ίδιο POS, 0% προμήθεια, το στήνουμε εμείς σε 10 λεπτά • Δωρεάν προβολή στα TikTok/Instagram της Anbit και στον χάρτη της Anbit Θα σας ενδιέφερε να σας το δείξουμε από κοντά σε 10 λεπτά, όποτε σας βολεύει;
A35: 31 | B35: Medez Cafe & Bar | C35: @medezcafe | D35: Άνοιγμα | E35: Μήνυμα | F35: Αθήνα | G35: Παγκράτι | H35: All-day Cafe-Bar | I35: A | L35: Δεν στάλθηκε | N35: =IF(M35="","",M35+4) | P35: =SUBSTITUTE(SUBSTITUTE(IF(I35="A",Μηνύματα!$B$7,Μηνύματα!$B$8),"{ΚΑΤΑΣΤΗΜΑ}",B35),"{ΟΝΟΜΑ}",Μηνύματα!$B$4) -> Γεια σας! 👋 Είμαι ο/η [Το όνομά σου] από την Anbit (anbit.gr). Μας άρεσε πολύ το Medez Cafe & Bar και θα θέλαμε να σας προτείνουμε μια συνεργασία. Η Anbit είναι παραγγελία από το τραπέζι με QR + σύστημα επιβράβευσης πελατών: • Ο πελάτης σκανάρει το QR, βλέπει το μενού με φωτογραφίες (Ελληνικά/Αγγλικά) και παραγγέλνει, χωρίς εφαρμογή • Η παραγγελία έρχεται στο κινητό ή στο tablet σας με τον αριθμό τραπεζιού • Με κάθε παραγγελία μαζεύει πόντους (XP) που εξαργυρώνονται μόνο στο δικό σας μαγαζί, οπότε έχει λόγο να ξαναέρθει • Βλέπετε ποιος έρχεται, πόσο συχνά και τι παίρνει • Δεν αλλάζει τίποτα στο ταμείο: ίδιο POS, 0% προμήθεια, το στήνουμε εμείς σε 10 λεπτά • Δωρεάν προβολή στα TikTok/Instagram της Anbit και στον χάρτη της Anbit Θα σας ενδιέφερε να σας το δείξουμε από κοντά σε 10 λεπτά, όποτε σας βολεύει;
A36: 32 | B36: Menta Cafe | C36: @menta_cafe_kifisia | D36: Άνοιγμα | E36: Μήνυμα | F36: Αθήνα | G36: Κηφισιά | H36: Cafe-Brunch-Dinner | I36: A | J36: Κήπος | L36: Δεν στάλθηκε | N36: =IF(M36="","",M36+4) | P36: =SUBSTITUTE(SUBSTITUTE(IF(I36="A",Μηνύματα!$B$7,Μηνύματα!$B$8),"{ΚΑΤΑΣΤΗΜΑ}",B36),"{ΟΝΟΜΑ}",Μηνύματα!$B$4) -> Γεια σας! 👋 Είμαι ο/η [Το όνομά σου] από την Anbit (anbit.gr). Μας άρεσε πολύ το Menta Cafe και θα θέλαμε να σας προτείνουμε μια συνεργασία. Η Anbit είναι παραγγελία από το τραπέζι με QR + σύστημα επιβράβευσης πελατών: • Ο πελάτης σκανάρει το QR, βλέπει το μενού με φωτογραφίες (Ελληνικά/Αγγλικά) και παραγγέλνει, χωρίς εφαρμογή • Η παραγγελία έρχεται στο κινητό ή στο tablet σας με τον αριθμό τραπεζιού • Με κάθε παραγγελία μαζεύει πόντους (XP) που εξαργυρώνονται μόνο στο δικό σας μαγαζί, οπότε έχει λόγο να ξαναέρθει • Βλέπετε ποιος έρχεται, πόσο συχνά και τι παίρνει • Δεν αλλάζει τίποτα στο ταμείο: ίδιο POS, 0% προμήθεια, το στήνουμε εμείς σε 10 λεπτά • Δωρεάν προβολή στα TikTok/Instagram της Anbit και στον χάρτη της Anbit Θα σας ενδιέφερε να σας το δείξουμε από κοντά σε 10 λεπτά, όποτε σας βολεύει;
A37: 33 | B37: MOKKA | C37: @mokkacoffee.athens | D37: Άνοιγμα | E37: Μήνυμα | F37: Αθήνα | H37: Specialty Coffee | I37: A | K37: Επιβεβαίωσε περιοχή | L37: Δεν στάλθηκε | N37: =IF(M37="","",M37+4) | P37: =SUBSTITUTE(SUBSTITUTE(IF(I37="A",Μηνύματα!$B$7,Μηνύματα!$B$8),"{ΚΑΤΑΣΤΗΜΑ}",B37),"{ΟΝΟΜΑ}",Μηνύματα!$B$4) -> Γεια σας! 👋 Είμαι ο/η [Το όνομά σου] από την Anbit (anbit.gr). Μας άρεσε πολύ το MOKKA και θα θέλαμε να σας προτείνουμε μια συνεργασία. Η Anbit είναι παραγγελία από το τραπέζι με QR + σύστημα επιβράβευσης πελατών: • Ο πελάτης σκανάρει το QR, βλέπει το μενού με φωτογραφίες (Ελληνικά/Αγγλικά) και παραγγέλνει, χωρίς εφαρμογή • Η παραγγελία έρχεται στο κινητό ή στο tablet σας με τον αριθμό τραπεζιού • Με κάθε παραγγελία μαζεύει πόντους (XP) που εξαργυρώνονται μόνο στο δικό σας μαγαζί, οπότε έχει λόγο να ξαναέρθει • Βλέπετε ποιος έρχεται, πόσο συχνά και τι παίρνει • Δεν αλλάζει τίποτα στο ταμείο: ίδιο POS, 0% προμήθεια, το στήνουμε εμείς σε 10 λεπτά • Δωρεάν προβολή στα TikTok/Instagram της Anbit και στον χάρτη της Anbit Θα σας ενδιέφερε να σας το δείξουμε από κοντά σε 10 λεπτά, όποτε σας βολεύει;
A38: 34 | B38: Morning Bar | C38: @morningbar.athens | D38: Άνοιγμα | E38: Μήνυμα | F38: Αθήνα | G38: Παγκράτι | H38: Breakfast / Coffee bar | I38: A | J38: Καθημερινές 09:00-17:00 | L38: Δεν στάλθηκε | N38: =IF(M38="","",M38+4) | P38: =SUBSTITUTE(SUBSTITUTE(IF(I38="A",Μηνύματα!$B$7,Μηνύματα!$B$8),"{ΚΑΤΑΣΤΗΜΑ}",B38),"{ΟΝΟΜΑ}",Μηνύματα!$B$4) -> Γεια σας! 👋 Είμαι ο/η [Το όνομά σου] από την Anbit (anbit.gr). Μας άρεσε πολύ το Morning Bar και θα θέλαμε να σας προτείνουμε μια συνεργασία. Η Anbit είναι παραγγελία από το τραπέζι με QR + σύστημα επιβράβευσης πελατών: • Ο πελάτης σκανάρει το QR, βλέπει το μενού με φωτογραφίες (Ελληνικά/Αγγλικά) και παραγγέλνει, χωρίς εφαρμογή • Η παραγγελία έρχεται στο κινητό ή στο tablet σας με τον αριθμό τραπεζιού • Με κάθε παραγγελία μαζεύει πόντους (XP) που εξαργυρώνονται μόνο στο δικό σας μαγαζί, οπότε έχει λόγο να ξαναέρθει • Βλέπετε ποιος έρχεται, πόσο συχνά και τι παίρνει • Δεν αλλάζει τίποτα στο ταμείο: ίδιο POS, 0% προμήθεια, το στήνουμε εμείς σε 10 λεπτά • Δωρεάν προβολή στα TikTok/Instagram της Anbit και στον χάρτη της Anbit Θα σας ενδιέφερε να σας το δείξουμε από κοντά σε 10 λεπτά, όποτε σας βολεύει;
A39: 35 | B39: Neratzia | C39: @neratzia.gr | D39: Άνοιγμα | E39: Μήνυμα | F39: Αθήνα | G39: Κουκάκι | H39: Cafe-Bistro | I39: A | J39: 08:00-01:00 (Π-Σ ως 02:00) | L39: Δεν στάλθηκε | N39: =IF(M39="","",M39+4) | P39: =SUBSTITUTE(SUBSTITUTE(IF(I39="A",Μηνύματα!$B$7,Μηνύματα!$B$8),"{ΚΑΤΑΣΤΗΜΑ}",B39),"{ΟΝΟΜΑ}",Μηνύματα!$B$4) -> Γεια σας! 👋 Είμαι ο/η [Το όνομά σου] από την Anbit (anbit.gr). Μας άρεσε πολύ το Neratzia και θα θέλαμε να σας προτείνουμε μια συνεργασία. Η Anbit είναι παραγγελία από το τραπέζι με QR + σύστημα επιβράβευσης πελατών: • Ο πελάτης σκανάρει το QR, βλέπει το μενού με φωτογραφίες (Ελληνικά/Αγγλικά) και παραγγέλνει, χωρίς εφαρμογή • Η παραγγελία έρχεται στο κινητό ή στο tablet σας με τον αριθμό τραπεζιού • Με κάθε παραγγελία μαζεύει πόντους (XP) που εξαργυρώνονται μόνο στο δικό σας μαγαζί, οπότε έχει λόγο να ξαναέρθει • Βλέπετε ποιος έρχεται, πόσο συχνά και τι παίρνει • Δεν αλλάζει τίποτα στο ταμείο: ίδιο POS, 0% προμήθεια, το στήνουμε εμείς σε 10 λεπτά • Δωρεάν προβολή στα TikTok/Instagram της Anbit και στον χάρτη της Anbit Θα σας ενδιέφερε να σας το δείξουμε από κοντά σε 10 λεπτά, όποτε σας βολεύει;
A40: 36 | B40: Num All Day Bar & Restaurant | C40: @num_veaki | D40: Άνοιγμα | E40: Μήνυμα | F40: Αθήνα | G40: Περιστέρι | H40: All-day Bar-Restaurant | I40: A | J40: Τηλ. 697 967 1566 | L40: Δεν στάλθηκε | N40: =IF(M40="","",M40+4) | P40: =SUBSTITUTE(SUBSTITUTE(IF(I40="A",Μηνύματα!$B$7,Μηνύματα!$B$8),"{ΚΑΤΑΣΤΗΜΑ}",B40),"{ΟΝΟΜΑ}",Μηνύματα!$B$4) -> Γεια σας! 👋 Είμαι ο/η [Το όνομά σου] από την Anbit (anbit.gr). Μας άρεσε πολύ το Num All Day Bar & Restaurant και θα θέλαμε να σας προτείνουμε μια συνεργασία. Η Anbit είναι παραγγελία από το τραπέζι με QR + σύστημα επιβράβευσης πελατών: • Ο πελάτης σκανάρει το QR, βλέπει το μενού με φωτογραφίες (Ελληνικά/Αγγλικά) και παραγγέλνει, χωρίς εφαρμογή • Η παραγγελία έρχεται στο κινητό ή στο tablet σας με τον αριθμό τραπεζιού • Με κάθε παραγγελία μαζεύει πόντους (XP) που εξαργυρώνονται μόνο στο δικό σας μαγαζί, οπότε έχει λόγο να ξαναέρθει • Βλέπετε ποιος έρχεται, πόσο συχνά και τι παίρνει • Δεν αλλάζει τίποτα στο ταμείο: ίδιο POS, 0% προμήθεια, το στήνουμε εμείς σε 10 λεπτά • Δωρεάν προβολή στα TikTok/Instagram της Anbit και στον χάρτη της Anbit Θα σας ενδιέφερε να σας το δείξουμε από κοντά σε 10 λεπτά, όποτε σας βολεύει;
A41: 37 | B41: Oubi | C41: @oubi.athens | D41: Άνοιγμα | E41: Μήνυμα | F41: Αθήνα | G41: Χαλάνδρι | H41: All-day Cafe-Brunch-Cocktails | I41: A | J41: Ήδη σε Wolt για delivery | L41: Δεν στάλθηκε | N41: =IF(M41="","",M41+4) | P41: =SUBSTITUTE(SUBSTITUTE(IF(I41="A",Μηνύματα!$B$7,Μηνύματα!$B$8),"{ΚΑΤΑΣΤΗΜΑ}",B41),"{ΟΝΟΜΑ}",Μηνύματα!$B$4) -> Γεια σας! 👋 Είμαι ο/η [Το όνομά σου] από την Anbit (anbit.gr). Μας άρεσε πολύ το Oubi και θα θέλαμε να σας προτείνουμε μια συνεργασία. Η Anbit είναι παραγγελία από το τραπέζι με QR + σύστημα επιβράβευσης πελατών: • Ο πελάτης σκανάρει το QR, βλέπει το μενού με φωτογραφίες (Ελληνικά/Αγγλικά) και παραγγέλνει, χωρίς εφαρμογή • Η παραγγελία έρχεται στο κινητό ή στο tablet σας με τον αριθμό τραπεζιού • Με κάθε παραγγελία μαζεύει πόντους (XP) που εξαργυρώνονται μόνο στο δικό σας μαγαζί, οπότε έχει λόγο να ξαναέρθει • Βλέπετε ποιος έρχεται, πόσο συχνά και τι παίρνει • Δεν αλλάζει τίποτα στο ταμείο: ίδιο POS, 0% προμήθεια, το στήνουμε εμείς σε 10 λεπτά • Δωρεάν προβολή στα TikTok/Instagram της Anbit και στον χάρτη της Anbit Θα σας ενδιέφερε να σας το δείξουμε από κοντά σε 10 λεπτά, όποτε σας βολεύει;
...

Sheet Μηνύματα
A1: Πρότυπα μηνυμάτων για Instagram DM
A2: Άλλαξε το κείμενο εδώ και ενημερώνεται αυτόματα η στήλη «Έτοιμο μήνυμα» στο φύλλο Λογαριασμοί. Το {ΚΑΤΑΣΤΗΜΑ} γίνεται το όνομα του μαγαζιού και το {ΟΝΟΜΑ} το όνομά σου.
A4: Το όνομά σου (συμπλήρωσε) | B4: [Το όνομά σου]
A6: Πρότυπο | B6: Κείμενο
A7: 1ο μήνυμα – Καφέ / All-day / Brunch (προτεραιότητα A) | B7: Γεια σας! 👋 Είμαι ο/η {ΟΝΟΜΑ} από την Anbit (anbit.gr). Μας άρεσε πολύ το {ΚΑΤΑΣΤΗΜΑ} και θα θέλαμε να σας προτείνουμε μια συνεργασία. Η Anbit είναι παραγγελία από το τραπέζι με QR + σύστημα επιβράβευσης πελατών: • Ο πελάτης σκανάρει το QR, βλέπει το μενού με φωτογραφίες (Ελληνικά/Αγγλικά) και παραγγέλνει, χωρίς εφαρμογή • Η παραγγελία έρχεται στο κινητό ή στο tablet σας με τον αριθμό τραπεζιού • Με κάθε παραγγελία μαζεύει πόντους (XP) που εξαργυρώνονται μόνο στο δικό σας μαγαζί, οπότε έχει λόγο να ξαναέρθει • Βλέπετε ποιος έρχεται, πόσο συχνά και τι παίρνει • Δεν αλλάζει τίποτα στο ταμείο: ίδιο POS, 0% προμήθεια, το στήνουμε εμείς σε 10 λεπτά • Δωρεάν προβολή στα TikTok/Instagram της Anbit και στον χάρτη της Anbit Θα σας ενδιέφερε να σας το δείξουμε από κοντά σε 10 λεπτά, όποτε σας βολεύει;
A8: 1ο μήνυμα – Bar / Ταβέρνα / Εστιατόριο / Street food (προτεραιότητα B, C) | B8: Γεια σας! 👋 Είμαι ο/η {ΟΝΟΜΑ} από την Anbit (anbit.gr). Είδαμε το {ΚΑΤΑΣΤΗΜΑ} και θα θέλαμε να σας προτείνουμε μια συνεργασία. Με την Anbit ο πελάτης σκανάρει ένα QR στο τραπέζι, βλέπει το μενού με φωτογραφίες σε Ελληνικά/Αγγλικά και παραγγέλνει χωρίς εφαρμογή. Η παραγγελία έρχεται κατευθείαν σε εσάς με τον αριθμό τραπεζιού, οπότε το προσωπικό κερδίζει χρόνο τις ώρες αιχμής. Επιπλέον ο πελάτης κερδίζει πόντους που εξαργυρώνει μόνο σε εσάς, οπότε έχει λόγο να επιστρέψει. Ίδιο POS, ίδια απόδειξη, 0% προμήθεια, και το στήνουμε εμείς σε 10 λεπτά. Σας προβάλλουμε επίσης δωρεάν στα social της Anbit. Θα θέλατε να σας στείλουμε περισσότερα ή να περάσουμε για μια σύντομη παρουσίαση;
A9: Follow-up (3-4 μέρες μετά, αν δεν απαντήσουν) | B9: Καλησπέρα ξανά από την Anbit! 😊 Ήθελα απλώς να δω αν είδατε το μήνυμά μου για το QR ordering με επιβράβευση πελατών για το {ΚΑΤΑΣΤΗΜΑ}. Αν σας ενδιαφέρει, περνάμε όποτε σας βολεύει για 10 λεπτά, χωρίς καμία δέσμευση. Μπορείτε να δείτε και περισσότερα στο anbit.gr
A10: Απάντηση: «Πόσο κοστίζει;» | B10: Ευχαριστούμε για το ενδιαφέρον! Η Anbit δεν παίρνει καμία προμήθεια από τις παραγγελίες (0%), αφού ο πελάτης πληρώνει όπως πάντα στο ταμείο σας. Το κόστος είναι [ΣΥΜΠΛΗΡΩΣΕ ΤΙΜΗ/ΠΑΚΕΤΟ]. Θέλετε να κλείσουμε μια σύντομη παρουσίαση για να το δείτε στην πράξη στο {ΚΑΤΑΣΤΗΜΑ};
